<?xml version="1.0" ?>
<!-- =================================================================================== -->
<!-- |    This document was autogenerated by xacro from ./limo_four_diff.xacro         | -->
<!-- |    EDITING THIS FILE BY HAND IS NOT RECOMMENDED                                 | -->
<!-- =================================================================================== -->
<robot name="limo_four_diff">
  <!-- Base link -->
  <link name="base_link">
    <visual>
      <!--origin xyz="0 0 -0.15" rpy="0 0 1.57" /-->
      <origin rpy="0 0 0" xyz="0 0 0"/>
      <geometry>
        <box size="0.13 0.12 0.1"/>
      </geometry>
    </visual>
    <collision>
      <!--origin xyz="0 0 -0.15" rpy="0 0 1.57" /-->
      <origin rpy="0 0 0" xyz="0 0 0"/>
      <geometry>
        <box size="0.13 0.12 0.1"/>
      </geometry>
    </collision>
    <inertial>
      <origin xyz="0.0 0.0 0.0"/>
      <mass value="2.1557"/>
      <inertia ixx="0.24" ixy="0" ixz="0" iyy="0.96" iyz="0" izz="0.96"/>
    </inertial>
  </link>
  <link name="laser_link">
    <inertial>
      <mass value="0.1"/>
      <origin rpy="0 0 0" xyz="0 0 0"/>
      <inertia ixx="1e-6" ixy="0" ixz="0" iyy="1e-6" iyz="0" izz="1e-6"/>
    </inertial>
    <visual name="laser_visual">
      <origin rpy="0 0 0" xyz="0 0 0"/>
      <geometry>
        <cylinder length="0.01" radius="0.02"/>
      </geometry>
      <!-- URDF material is okay, but Webots may ignore it; harmless -->
      <material name="laser_material">
        <color rgba="0.1 0.1 0.2 1"/>
      </material>
    </visual>
    <collision name="laser_collision">
      <origin rpy="0 0 0" xyz="0 0 0"/>
      <geometry>
        <cylinder length="0.016" radius="0.032"/>
      </geometry>
    </collision>
  </link>
  <joint name="laser_joint" type="fixed">
    <origin rpy="0 0 0" xyz="0.103 0 -0.034"/>
    <parent link="base_link"/>
    <child link="laser_link"/>
  </joint>
  <link name="imu_link">
    <inertial>
      <mass value="0.01"/>
      <origin rpy="0 0 0" xyz="0 0 0"/>
      <inertia ixx="1e-7" ixy="0" ixz="0" iyy="1e-7" iyz="0" izz="1e-7"/>
    </inertial>
    <visual name="imu_visual">
      <origin rpy="0 0 0" xyz="0 0 0"/>
      <geometry>
        <box size="0.01 0.01 0.01"/>
      </geometry>
      <material name="imu_material">
        <color rgba="0.1 0.1 0.2 1"/>
      </material>
    </visual>
    <collision name="imu_collision">
      <origin rpy="0 0 0" xyz="0 0 0"/>
      <geometry>
        <box size="0.01 0.01 0.01"/>
      </geometry>
    </collision>
  </link>
  <joint name="imu_joint" type="fixed">
    <origin rpy="0 0 0" xyz="0.0 0 -0.1"/>
    <parent link="base_link"/>
    <child link="imu_link"/>
  </joint>
  <link name="depth_camera_link">
    <inertial>
      <mass value="0.1"/>
      <origin rpy="0 0 0" xyz="0.0 0 0"/>
      <inertia ixx="1e-6" ixy="0" ixz="0" iyy="1e-6" iyz="0" izz="1e-6"/>
    </inertial>
    <visual name="depth_camera_visual">
      <origin rpy="0 0 0" xyz="0 0 0"/>
      <geometry>
        <box size="0.02 0.06 0.015"/>
      </geometry>
      <material name="depth_camera_material">
        <color rgba="0.3 0.1 0.1 1"/>
      </material>
    </visual>
    <collision name="depth_camera_collision">
      <origin rpy="0 0 0" xyz="0 0 0"/>
      <geometry>
        <box size="0.02 0.06 0.015"/>
      </geometry>
    </collision>
  </link>
  <joint name="depth_camera_joint" type="fixed">
    <origin rpy="0 0 0" xyz="0.12 0 0.06"/>
    <child link="depth_camera_link"/>
    <parent link="base_link"/>
  </joint>
  <link name="depth_link"/>
  <joint name="depth_camera_to_camera_joint" type="fixed">
    <origin rpy="-1.570795 0 -1.570795 " xyz="0 0 0"/>
    <parent link="depth_camera_link"/>
    <child link="depth_link"/>
  </joint>
  <link name="front_left_wheel_link">
    <inertial>
      <origin rpy="0 0 0" xyz="0 0 0"/>
      <mass value="0.5"/>
      <inertia ixx="0.01055" ixy="0" ixz="0" iyy="0.00075" iyz="0" izz="0.01055"/>
    </inertial>
    <visual>
      <origin rpy="1.5708 0 0" xyz="0 0.0225 0"/>
      <geometry>
        <cylinder length="0.045" radius="0.045"/>
      </geometry>
      <material name="front_left_material">
        <color rgba="0.0 0.0 0.0 1"/>
      </material>
    </visual>
    <collision>
      <!-- Cylinder is rotated so its axis matches joint axis (Y) -->
      <origin rpy="1.5708 0 0" xyz="0 0.0225 0"/>
      <geometry>
        <cylinder length="0.045" radius="0.045"/>
      </geometry>
    </collision>
  </link>
  <joint name="front_left_wheel_joint" type="continuous">
    <parent link="base_link"/>
    <child link="front_left_wheel_link"/>
    <origin rpy="0 0  0" xyz="0.1 0.065 -0.1"/>
    <!-- Wheel rotation axis in parent frame -->
    <axis xyz="0 1 0"/>
  </joint>
  <link name="front_right_wheel_link">
    <inertial>
      <origin rpy="0 0 0" xyz="0 0 0"/>
      <mass value="0.5"/>
      <inertia ixx="0.01055" ixy="0" ixz="0" iyy="0.00075" iyz="0" izz="0.01055"/>
    </inertial>
    <visual>
      <origin rpy="1.5708 0 0" xyz="0 0.0225 0"/>
      <geometry>
        <cylinder length="0.045" radius="0.045"/>
      </geometry>
      <material name="front_right_material">
        <color rgba="0.0 0.0 0.0 1"/>
      </material>
    </visual>
    <collision>
      <!-- Cylinder is rotated so its axis matches joint axis (Y) -->
      <origin rpy="1.5708 0 0" xyz="0 0.0225 0"/>
      <geometry>
        <cylinder length="0.045" radius="0.045"/>
      </geometry>
    </collision>
  </link>
  <joint name="front_right_wheel_joint" type="continuous">
    <parent link="base_link"/>
    <child link="front_right_wheel_link"/>
    <origin rpy="3.14159 0 0" xyz="0.1 -0.065 -0.1"/>
    <!-- Wheel rotation axis in parent frame -->
    <axis xyz="0 -1 0"/>
  </joint>
  <link name="rear_left_wheel_link">
    <inertial>
      <origin rpy="0 0 0" xyz="0 0 0"/>
      <mass value="0.5"/>
      <inertia ixx="0.01055" ixy="0" ixz="0" iyy="0.00075" iyz="0" izz="0.01055"/>
    </inertial>
    <visual>
      <origin rpy="1.5708 0 0" xyz="0 0.0225 0"/>
      <geometry>
        <cylinder length="0.045" radius="0.045"/>
      </geometry>
      <material name="rear_left_material">
        <color rgba="0.0 0.0 0.0 1"/>
      </material>
    </visual>
    <collision>
      <!-- Cylinder is rotated so its axis matches joint axis (Y) -->
      <origin rpy="1.5708 0 0" xyz="0 0.0225 0"/>
      <geometry>
        <cylinder length="0.045" radius="0.045"/>
      </geometry>
    </collision>
  </link>
  <joint name="rear_left_wheel_joint" type="continuous">
    <parent link="base_link"/>
    <child link="rear_left_wheel_link"/>
    <origin rpy="0 0 0" xyz="-0.1 0.065 -0.1"/>
    <!-- Wheel rotation axis in parent frame -->
    <axis xyz="0 1 0"/>
  </joint>
  <link name="rear_right_wheel_link">
    <inertial>
      <origin rpy="0 0 0" xyz="0 0 0"/>
      <mass value="0.5"/>
      <inertia ixx="0.01055" ixy="0" ixz="0" iyy="0.00075" iyz="0" izz="0.01055"/>
    </inertial>
    <visual>
      <origin rpy="1.5708 0 0" xyz="0 0.0225 0"/>
      <geometry>
        <cylinder length="0.045" radius="0.045"/>
      </geometry>
      <material name="rear_right_material">
        <color rgba="0.0 0.0 0.0 1"/>
      </material>
    </visual>
    <collision>
      <!-- Cylinder is rotated so its axis matches joint axis (Y) -->
      <origin rpy="1.5708 0 0" xyz="0 0.0225 0"/>
      <geometry>
        <cylinder length="0.045" radius="0.045"/>
      </geometry>
    </collision>
  </link>
  <joint name="rear_right_wheel_joint" type="continuous">
    <parent link="base_link"/>
    <child link="rear_right_wheel_link"/>
    <origin rpy="3.14159 0 0" xyz="-0.1 -0.065 -0.1"/>
    <!-- Wheel rotation axis in parent frame -->
    <axis xyz="0 -1 0"/>
  </joint>
</robot>
